File: NewTestData.csv
SS316LN,laser pulse duration (ns),laser energy (mJ),loding rate (µN/s),Depth (nm),load (µN) ,time (s)
,0.00001,0.00001,2500,0,9.582889,0
,0.00001,0.00001,2500,49.203088,681.109952,0.13513
,0.00001,0.00001,2500,82.158681,1356.671355,0.270259
,0.00001,0.00001,2500,108.805387,2034.509059,0.405389
,0.00001,0.00001,2500,132.671588,2713.93292,0.540518
,0.00001,0.00001,2500,153.659854,3394.46073,0.675648
,0.00001,0.00001,2500,174.101899,4075.77043,0.810778
,0.00001,0.00001,2500,192.313702,4758.651715,0.945907
,0.00001,0.00001,2500,208.216597,5441.879685,1.081037
,0.00001,0.00001,2500,225.575059,6125.704035,1.216166
,0.00001,0.00001,2500,239.836217,6810.481096,1.351296
,0.00001,0.00001,2500,254.614007,7495.735832,1.486426
,0.00001,0.00001,2500,266.179229,8043.978892,1.621555
,0.00001,0.00001,2500,268.780473,8044.130737,1.756685
,0.00001,0.00001,2500,270.51968,8044.186918,1.891814
,0.00001,0.00001,2500,271.095148,8044.204165,2.026944
,0.00001,0.00001,2500,271.54344,8044.219827,2.162074
,0.00001,0.00001,2500,271.849293,8044.2194,2.297203
,0.00001,0.00001,2500,272.457257,8044.203404,2.432333
,0.00001,0.00001,2500,272.984291,8044.212256,2.567462
,0.00001,0.00001,2500,273.468977,8044.236999,2.702592
,0.00001,0.00001,2500,273.696182,8044.28963,2.837722
,0.00001,0.00001,2500,273.88283,8044.274777,2.972851
,0.00001,0.00001,2500,274.063217,8044.277838,3.107981
,0.00001,0.00001,2500,274.185043,8044.290298,3.24311
,0.00001,0.00001,2500,274.424437,8044.292017,3.37824
,0.00001,0.00001,2500,274.387019,8044.285893,3.51337
,0.00001,0.00001,2500,274.712539,8044.317192,3.648499
,0.00001,0.00001,2500,274.646006,8044.305218,3.783629
,0.00001,0.00001,2500,274.917377,8044.294778,3.918758
,0.00001,0.00001,2500,275.051638,8044.306586,4.053888
,0.00001,0.00001,2500,275.20976,8044.321082,4.189018
,0.00001,0.00001,2500,275.259841,8044.29834,4.324147
,0.00001,0.00001,2500,275.33071,8044.305337,4.459277
,0.00001,0.00001,2500,275.352527,8044.299887,4.594406
,0.00001,0.00001,2500,275.510832,8044.315394,4.729536
,0.00001,0.00001,2500,275.596137,8044.313754,4.864666
,0.00001,0.00001,2500,275.648799,8044.292091,4.999795
,0.00001,0.00001,2500,275.893631,8044.326134,5.134925
,0.00001,0.00001,2500,276.117976,8044.302302,5.270054
,0.00001,0.00001,2500,276.017071,8044.320513,5.405184
,0.00001,0.00001,2500,276.026433,8044.313706,5.540314
,0.00001,0.00001,2500,276.081642,8044.335338,5.675443
,0.00001,0.00001,2500,276.1587,8044.30733,5.810573
,0.00001,0.00001,2500,276.181828,8044.336094,5.945702
,0.00001,0.00001,2500,276.349469,8044.333775,6.080832
,0.00001,0.00001,2500,276.440354,8044.307164,6.215962
,0.00001,0.00001,2500,276.455658,8044.32666,6.351091
,0.00001,0.00001,2500,276.535839,8044.334929,6.486221
,0.00001,0.00001,2500,276.544775,8044.340171,6.62135
,0.00001,0.00001,2500,276.803566,8044.341443,6.75648
,0.00001,0.00001,2500,276.871473,8044.369468,6.89161
,0.00001,0.00001,2500,276.772461,8044.356571,7.026739
,0.00001,0.00001,2500,276.90272,8044.330073,7.161869
,0.00001,0.00001,2500,276.914088,8044.322317,7.296998
,0.00001,0.00001,2500,277.222798,8044.334053,7.432128
,0.00001,0.00001,2500,277.058731,8044.357509,7.567258
,0.00001,0.00001,2500,277.084094,8044.349145,7.702387
,0.00001,0.00001,2500,277.256193,8044.332881,7.837517
,0.00001,0.00001,2500,277.292286,8044.344926,7.972646
,0.00001,0.00001,2500,277.298704,8044.352108,8.107776
,0.00001,0.00001,2500,277.265903,8044.371246,8.242906
,0.00001,0.00001,2500,277.398119,8044.362898,8.378035
,0.00001,0.00001,2500,277.399416,8044.359883,8.513165
,0.00001,0.00001,2500,277.465219,8044.353672,8.648295
,0.00001,0.00001,2500,277.344506,8044.359258,8.783424
,0.00001,0.00001,2500,277.54938,8044.375087,8.918554
,0.00001,0.00001,2500,277.537301,8044.357619,9.053683
,0.00001,0.00001,2500,277.555962,8044.357107,9.188813
,0.00001,0.00001,2500,277.554314,8044.339935,9.323943
,0.00001,0.00001,2500,277.67962,8044.366575,9.459072
,0.00001,0.00001,2500,277.718925,8044.360618,9.594202
,0.00001,0.00001,2500,277.676285,8044.366408,9.729331
,0.00001,0.00001,2500,277.701525,8044.370104,9.864461
,0.00001,0.00001,2500,277.709683,8044.379347,9.999591
,0.00001,0.00001,2500,277.78842,8044.387577,10.13472
,0.00001,0.00001,2500,277.897241,8044.395656,10.26985
,0.00001,0.00001,2500,277.962713,8044.419594,10.404979
,0.00001,0.00001,2500,277.959723,8044.389315,10.540109
,0.00001,0.00001,2500,277.818274,8044.409391,10.675239
,0.00001,0.00001,2500,277.723791,8044.382547,10.810368
,0.00001,0.00001,2500,277.82639,8044.383412,10.945498
,0.00001,0.00001,2500,278.020462,8044.417033,11.080627
,0.00001,0.00001,2500,278.135677,8044.419262,11.215757
,0.00001,0.00001,2500,277.977879,8044.421784,11.350887
,0.00001,0.00001,2500,278.052228,8044.424864,11.486016
,0.00001,0.00001,2500,277.630663,7982.769237,11.621146
,0.00001,0.00001,2500,275.50443,7297.123167,11.756275
,0.00001,0.00001,2500,273.188929,6611.043808,11.891405
,0.00001,0.00001,2500,270.746168,5925.498726,12.026535
,0.00001,0.00001,2500,268.32014,5239.817322,12.161664
,0.00001,0.00001,2500,265.740676,4554.178987,12.296794
,0.00001,0.00001,2500,262.861971,3868.963802,12.431923
,0.00001,0.00001,2500,260.051901,3183.956348,12.567053
,0.00001,0.00001,2500,257.224229,2499.032717,12.702183
,0.00001,0.00001,2500,253.9144,1814.109781,12.837312
,0.00001,0.00001,2500,250.259282,1129.63446,12.972442
,0.00001,0.00001,2500,245.342827,445.432611,13.107571
,0.03,5,2500,5.641936,81.886761,0.030029
,0.03,5,2500,32.434449,416.201174,0.165158
,0.03,5,2500,52.603497,752.257412,0.300288
,0.03,5,2500,69.75906,1089.135964,0.435418
,0.03,5,2500,84.512182,1426.680617,0.570547
,0.03,5,2500,97.983743,1764.764578,0.705677
,0.03,5,2500,109.516761,2103.726025,0.840806
,0.03,5,2500,119.443563,2442.736896,0.975936
,0.03,5,2500,129.248313,2781.969129,1.111066
,0.03,5,2500,138.318878,3121.558705,1.246195
,0.03,5,2500,147.032118,3461.338812,1.381325
,0.03,5,2500,155.471151,3801.359425,1.516454
,0.03,5,2500,163.592683,4141.60513,1.651584
,0.03,5,2500,171.218474,4481.920273,1.786714
,0.03,5,2500,179.240282,4822.793104,1.921843
,0.03,5,2500,186.642881,5163.553893,2.056973
,0.03,5,2500,193.595009,5504.462305,2.192102
,0.03,5,2500,200.918488,5845.65602,2.327232
,0.03,5,2500,207.857403,6186.79192,2.462362
,0.03,5,2500,214.744862,6527.973209,2.597491
,0.03,5,2500,220.986501,6869.712382,2.732621
,0.03,5,2500,227.467119,7211.205743,2.86775
,0.03,5,2500,233.399456,7553.052634,3.00288
,0.03,5,2500,239.089369,7894.930063,3.13801
,0.03,5,2500,243.365068,8042.147615,3.273139
,0.03,5,2500,244.763361,8042.17257,3.408269
,0.03,5,2500,245.622988,8042.159889,3.543398
,0.03,5,2500,246.297121,8042.187666,3.678528
,0.03,5,2500,246.873309,8042.191916,3.813658
,0.03,5,2500,246.934088,8042.197205,3.948787
,0.03,5,2500,247.55724,8042.229723,4.083917
,0.03,5,2500,247.879567,8042.247631,4.219046
,0.03,5,2500,248.074977,8042.272366,4.354176
,0.03,5,2500,248.398954,8042.245185,4.489306
,0.03,5,2500,248.41391,8042.259348,4.624435
,0.03,5,2500,248.747241,8042.290575,4.759565
,0.03,5,2500,248.92031,8042.263597,4.894694
,0.03,5,2500,249.039015,8042.29041,5.029824
,0.03,5,2500,249.240245,8042.315295,5.164954
,0.03,5,2500,249.331492,8042.288257,5.300083
,0.03,5,2500,249.309328,8042.285435,5.435213
,0.03,5,2500,249.51248,8042.277271,5.570342
,0.03,5,2500,249.731688,8042.310635,5.705472
,0.03,5,2500,249.722132,8042.285063,5.840602
,0.03,5,2500,249.86206,8042.298371,5.975731
,0.03,5,2500,250.124698,8042.292713,6.110861
,0.03,5,2500,250.042777,8042.293397,6.24599
,0.03,5,2500,250.271427,8042.284874,6.38112
,0.03,5,2500,250.263197,8042.306477,6.51625
,0.03,5,2500,250.257168,8042.32312,6.651379
,0.03,5,2500,250.313629,8042.295203,6.786509
,0.03,5,2500,250.483828,8042.289216,6.921638
,0.03,5,2500,250.499119,8042.337492,7.056768
,0.03,5,2500,250.598318,8042.314666,7.191898
,0.03,5,2500,250.762865,8042.306531,7.327027
,0.03,5,2500,250.760233,8042.333291,7.462157
,0.03,5,2500,250.816491,8042.284305,7.597286
,0.03,5,2500,250.782142,8042.294215,7.732416
,0.03,5,2500,250.929149,8042.297673,7.867546
,0.03,5,2500,250.934246,8042.306573,8.002675
,0.03,5,2500,251.004932,8042.298073,8.137805
,0.03,5,2500,251.041705,8042.303761,8.272934
,0.03,5,2500,251.12545,8042.315651,8.408064
,0.03,5,2500,251.312421,8042.288023,8.543194
,0.03,5,2500,251.146312,8042.294603,8.678323
,0.03,5,2500,251.396039,8042.302663,8.813453
,0.03,5,2500,251.377669,8042.309968,8.948583
,0.03,5,2500,251.359766,8042.326311,9.083712
,0.03,5,2500,251.175116,8042.29832,9.218842
,0.03,5,2500,251.479219,8042.303742,9.353971
,0.03,5,2500,251.321536,8042.311538,9.489101
,0.03,5,2500,251.503155,8042.310856,9.624231
,0.03,5,2500,251.528071,8042.318251,9.75936
,0.03,5,2500,251.612197,8042.308085,9.89449
,0.03,5,2500,251.750085,8042.317331,10.029619
,0.03,5,2500,251.574297,8042.31163,10.164749
,0.03,5,2500,251.610672,8042.299254,10.299879
,0.03,5,2500,251.720995,8042.297774,10.435008
,0.03,5,2500,251.761278,8042.305557,10.570138
,0.03,5,2500,251.800758,8042.308305,10.705267
,0.03,5,2500,251.853557,8042.320417,10.840397
,0.03,5,2500,251.851925,8042.32012,10.975527
,0.03,5,2500,251.95684,8042.311482,11.110656
,0.03,5,2500,251.997696,8042.304234,11.245786
,0.03,5,2500,251.962647,8042.305099,11.380915
,0.03,5,2500,252.114133,8042.314689,11.516045
,0.03,5,2500,252.081448,8042.310598,11.651175
,0.03,5,2500,252.07714,8042.300203,11.786304
,0.03,5,2500,252.185884,8042.324763,11.921434
,0.03,5,2500,252.037082,8042.300685,12.056563
,0.03,5,2500,252.135699,8042.324989,12.191693
,0.03,5,2500,252.203008,8042.335461,12.326823
,0.03,5,2500,252.322097,8042.311133,12.461952
,0.03,5,2500,252.270069,8042.313574,12.597082
,0.03,5,2500,252.383025,8042.330216,12.732211
,0.03,5,2500,252.415325,8042.317737,12.867341
,0.03,5,2500,252.432295,8042.308882,13.002471
,0.03,5,2500,252.476275,8042.318765,13.1376
,0.03,5,2500,251.936817,7884.754672,13.27273
,0.03,5,2500,250.655623,7542.64808,13.407859
,0.03,5,2500,249.25982,7200.737441,13.542989
,0.03,5,2500,247.927165,6858.789712,13.678119
,0.03,5,2500,246.710417,6517.067276,13.813248
,0.03,5,2500,245.284236,6175.190896,13.948378
,0.03,5,2500,244.064409,5833.293377,14.083507
,0.03,5,2500,242.708585,5491.634729,14.218637
,0.03,5,2500,241.164089,5149.825684,14.353767
,0.03,5,2500,239.815359,4808.179194,14.488896
,0.03,5,2500,238.329107,4466.273465,14.624026
,0.03,5,2500,236.803057,4124.714207,14.759155
,0.03,5,2500,235.098357,3783.252241,14.894285
,0.03,5,2500,233.726801,3441.720594,15.029415
,0.03,5,2500,231.916461,3100.313234,15.164544
,0.03,5,2500,230.348334,2758.884975,15.299674
,0.03,5,2500,228.497172,2417.647066,15.434803
,0.03,5,2500,226.573379,2076.327713,15.569933
,0.03,5,2500,224.826501,1734.822836,15.705063
,0.03,5,2500,222.438422,1393.732639,15.840192
,0.03,5,2500,220.335678,1052.687343,15.975322
,0.03,5,2500,217.600844,711.736675,16.110451
,0.03,5,2500,214.487797,370.833327,16.245581
,0.03,5,2500,210.152233,30.276431,16.380711
,0.03,10,2500,20.848152,255.024865,0.100096
,0.03,10,2500,40.708033,590.958446,0.235226
,0.03,10,2500,56.128911,927.903884,0.370355
,0.03,10,2500,69.025121,1265.665722,0.505485
,0.03,10,2500,80.345151,1603.884924,0.640614
,0.03,10,2500,91.326701,1942.422004,0.775744
,0.03,10,2500,100.852662,2281.442209,0.910874
,0.03,10,2500,109.98237,2620.767723,1.046003
,0.03,10,2500,118.482,2960.187463,1.181133
,0.03,10,2500,126.437232,3299.748266,1.316262
,0.03,10,2500,133.929581,3639.679956,1.451392
,0.03,10,2500,141.196923,3979.703094,1.586522
,0.03,10,2500,148.238334,4319.940417,1.721651
,0.03,10,2500,155.164896,4660.773146,1.856781
,0.03,10,2500,161.517655,5001.331097,1.99191
,0.03,10,2500,167.872599,5341.899906,2.12704
,0.03,10,2500,173.855383,5682.744052,2.26217
,0.03,10,2500,179.664127,6023.885533,2.397299
,0.03,10,2500,185.319243,6364.914227,2.532429
,0.03,10,2500,190.659075,6706.016718,2.667558
,0.03,10,2500,196.0148,7047.737821,2.802688
,0.03,10,2500,201.187644,7389.046016,2.937818
,0.03,10,2500,205.984862,7730.85666,3.072947
,0.03,10,2500,210.561178,8042.090098,3.208077
,0.03,10,2500,212.319714,8042.19034,3.343206
,0.03,10,2500,213.135388,8042.22479,3.478336
,0.03,10,2500,213.576296,8042.249952,3.613466
,0.03,10,2500,213.983869,8042.234122,3.748595
,0.03,10,2500,214.134173,8042.226814,3.883725
,0.03,10,2500,214.502745,8042.266566,4.018854
,0.03,10,2500,214.518794,8042.266826,4.153984
,0.03,10,2500,214.807295,8042.27702,4.289114
,0.03,10,2500,215.057467,8042.287953,4.424243
,0.03,10,2500,215.266766,8042.311511,4.559373
,0.03,10,2500,215.438199,8042.290932,4.694502
,0.03,10,2500,215.639739,8042.251389,4.829632
,0.03,10,2500,215.719608,8042.299632,4.964762
,0.03,10,2500,215.859058,8042.256057,5.099891
,0.03,10,2500,216.020682,8042.27506,5.235021
,0.03,10,2500,216.114426,8042.286848,5.37015
,0.03,10,2500,216.195046,8042.295213,5.50528
,0.03,10,2500,216.189301,8042.304734,5.64041
,0.03,10,2500,216.162941,8042.326548,5.775539
,0.03,10,2500,216.301869,8042.314879,5.910669
,0.03,10,2500,216.565216,8042.290334,6.045798
,0.03,10,2500,216.46249,8042.299665,6.180928
,0.03,10,2500,216.60093,8042.315913,6.316058
,0.03,10,2500,216.520037,8042.31,6.451187
,0.03,10,2500,216.715012,8042.307154,6.586317
,0.03,10,2500,216.708861,8042.292719,6.721446
,0.03,10,2500,216.806326,8042.287671,6.856576
,0.03,10,2500,216.846795,8042.280752,6.991706
,0.03,10,2500,216.71697,8042.251285,7.126835
,0.03,10,2500,216.983868,8042.296689,7.261965
,0.03,10,2500,217.024965,8042.317724,7.397094
,0.03,10,2500,217.178791,8042.270631,7.532224
,0.03,10,2500,217.249633,8042.306609,7.667354
,0.03,10,2500,217.168949,8042.272768,7.802483
,0.03,10,2500,217.187769,8042.254165,7.937613
,0.03,10,2500,217.235879,8042.264457,8.072742
,0.03,10,2500,217.202083,8042.271062,8.207872
,0.03,10,2500,217.283666,8042.257512,8.343002
,0.03,10,2500,217.205229,8042.293578,8.478131
,0.03,10,2500,217.276568,8042.279692,8.613261
,0.03,10,2500,217.206737,8042.301076,8.748391
,0.03,10,2500,217.377121,8042.299419,8.88352
,0.03,10,2500,217.40183,8042.290985,9.01865
,0.03,10,2500,217.432858,8042.278768,9.153779
,0.03,10,2500,217.42748,8042.281319,9.288909
,0.03,10,2500,217.410915,8042.287492,9.424039
,0.03,10,2500,217.726945,8042.257694,9.559168
,0.03,10,2500,217.537314,8042.279137,9.694298
,0.03,10,2500,217.632737,8042.26205,9.829427
,0.03,10,2500,217.882464,8042.264993,9.964557
,0.03,10,2500,217.612842,8042.31773,10.099687
,0.03,10,2500,217.691103,8042.329011,10.234816
,0.03,10,2500,217.73152,8042.268219,10.369946
,0.03,10,2500,217.748094,8042.30042,10.505075
,0.03,10,2500,217.657614,8042.32013,10.640205
,0.03,10,2500,217.719627,8042.338859,10.775335
,0.03,10,2500,217.737379,8042.300268,10.910464
,0.03,10,2500,217.957232,8042.331162,11.045594
,0.03,10,2500,217.899525,8042.345961,11.180723
,0.03,10,2500,217.947129,8042.307352,11.315853
,0.03,10,2500,217.809258,8042.301562,11.450983
,0.03,10,2500,217.899723,8042.330204,11.586112
,0.03,10,2500,217.949398,8042.310618,11.721242
,0.03,10,2500,218.001567,8042.271162,11.856371
,0.03,10,2500,217.987204,8042.300353,11.991501
,0.03,10,2500,218.048615,8042.327044,12.126631
,0.03,10,2500,218.037137,8042.319417,12.26176
,0.03,10,2500,217.815658,8042.301904,12.39689
,0.03,10,2500,218.081647,8042.291414,12.532019
,0.03,10,2500,218.007404,8042.326621,12.667149
,0.03,10,2500,218.180426,8042.31308,12.802279
,0.03,10,2500,218.055764,8042.313709,12.937408
,0.03,10,2500,218.274801,8042.27973,13.072538
,0.03,10,2500,218.185916,8042.294504,13.207667
,0.03,10,2500,216.893812,7707.72217,13.342797
,0.03,10,2500,215.624792,7366.086643,13.477927
,0.03,10,2500,214.265107,7024.299747,13.613056
,0.03,10,2500,212.942146,6682.88367,13.748186
,0.03,10,2500,211.581742,6341.347143,13.883315
,0.03,10,2500,210.045602,5999.692167,14.018445
,0.03,10,2500,208.613961,5658.355143,14.153575
,0.03,10,2500,207.062564,5316.94473,14.288704
,0.03,10,2500,205.524617,4975.565485,14.423834
,0.03,10,2500,204.062937,4634.322095,14.558963
,0.03,10,2500,202.393123,4292.703234,14.694093
,0.03,10,2500,200.730405,3951.543009,14.829223
,0.03,10,2500,199.029987,3610.164928,14.964352
,0.03,10,2500,197.251898,3269.049778,15.099482
,0.03,10,2500,195.466748,2927.969464,15.234611
,0.03,10,2500,193.702266,2586.95279,15.369741
,0.03,10,2500,191.817542,2245.880698,15.504871
,0.03,10,2500,189.720893,1904.831873,15.64
,0.03,10,2500,187.51895,1563.988119,15.77513
,0.03,10,2500,185.212372,1223.188937,15.910259
,0.03,10,2500,182.722308,882.48349,16.045389
,0.03,10,2500,179.762216,541.943334,16.180519
,0.03,10,2500,175.901988,201.486365,16.315648
,0.03,15,2500,8.032122,92.004184,0.035034
,0.03,15,2500,35.623295,426.276501,0.170163
,0.03,15,2500,53.173451,762.952699,0.305293
,0.03,15,2500,68.931567,1100.153681,0.440422
,0.03,15,2500,83.057432,1437.971093,0.575552
,0.03,15,2500,95.6188,1776.241405,0.710682
,0.03,15,2500,107.131086,2115.258985,0.845811
,0.03,15,2500,118.233248,2454.238983,0.980941
,0.03,15,2500,127.970605,2793.671078,1.11607
,0.03,15,2500,137.357537,3133.346338,1.2512
,0.03,15,2500,146.033004,3473.185605,1.38633
,0.03,15,2500,154.057141,3813.379453,1.521459
,0.03,15,2500,161.624508,4153.734081,1.656589
,0.03,15,2500,168.990976,4494.40091,1.791718
,0.03,15,2500,175.938885,4835.391321,1.926848
,0.03,15,2500,182.787663,5176.165994,2.061978
,0.03,15,2500,189.425914,5517.354898,2.197107
,0.03,15,2500,195.793185,5858.65316,2.332237
,0.03,15,2500,201.972043,6199.781304,2.467366
,0.03,15,2500,207.812754,6541.228873,2.602496
,0.03,15,2500,213.458015,6882.871838,2.737626
,0.03,15,2500,218.574251,7224.467067,2.872755
,0.03,15,2500,223.23266,7566.437321,3.007885
,0.03,15,2500,227.590773,7908.283728,3.143014
,0.03,15,2500,230.686399,8042.456979,3.278144
,0.03,15,2500,231.791927,8042.467356,3.413274
,0.03,15,2500,232.463776,8042.488158,3.548403
,0.03,15,2500,232.923847,8042.492327,3.683533
,0.03,15,2500,233.190241,8042.494429,3.818662
,0.03,15,2500,233.559443,8042.521758,3.953792
,0.03,15,2500,233.783376,8042.538533,4.088922
,0.03,15,2500,234.194369,8042.512165,4.224051
,0.03,15,2500,234.213281,8042.528516,4.359181
,0.03,15,2500,234.556579,8042.57004,4.49431
,0.03,15,2500,234.788047,8042.553048,4.62944
,0.03,15,2500,234.916328,8042.550824,4.76457
,0.03,15,2500,235.096464,8042.576232,4.899699
,0.03,15,2500,235.179615,8042.556591,5.034829
,0.03,15,2500,235.349663,8042.556678,5.169958
,0.03,15,2500,235.396288,8042.552894,5.305088
,0.03,15,2500,235.521217,8042.56857,5.440218
,0.03,15,2500,235.500614,8042.557677,5.575347
,0.03,15,2500,235.841418,8042.600129,5.710477
,0.03,15,2500,235.852047,8042.586215,5.845606
,0.03,15,2500,236.070151,8042.605815,5.980736
,0.03,15,2500,235.901069,8042.592264,6.115866
,0.03,15,2500,236.163839,8042.600263,6.250995
,0.03,15,2500,236.198939,8042.596118,6.386125
,0.03,15,2500,236.307641,8042.620289,6.521254
,0.03,15,2500,236.538897,8042.641305,6.656384
,0.03,15,2500,236.60642,8042.633176,6.791514
,0.03,15,2500,236.561439,8042.621518,6.926643
,0.03,15,2500,236.673072,8042.637779,7.061773
,0.03,15,2500,236.622327,8042.649946,7.196902
,0.03,15,2500,236.848433,8042.672802,7.332032
,0.03,15,2500,236.828096,8042.648912,7.467162
,0.03,15,2500,237.153756,8042.666891,7.602291
,0.03,15,2500,237.102357,8042.680038,7.737421
,0.03,15,2500,237.216977,8042.665386,7.87255
,0.03,15,2500,237.294002,8042.665559,8.00768
,0.03,15,2500,237.361064,8042.692427,8.14281
,0.03,15,2500,237.320098,8042.667889,8.277939
,0.03,15,2500,237.323763,8042.663759,8.413069
,0.03,15,2500,237.489555,8042.661717,8.548198
,0.03,15,2500,237.49864,8042.678763,8.683328
,0.03,15,2500,237.546765,8042.671027,8.818458
,0.03,15,2500,237.48157,8042.660733,8.953587
,0.03,15,2500,237.580368,8042.669592,9.088717
,0.03,15,2500,237.5131,8042.678239,9.223847
,0.03,15,2500,237.777345,8042.664284,9.358976
,0.03,15,2500,237.736888,8042.668772,9.494106
,0.03,15,2500,237.726273,8042.677197,9.629235
,0.03,15,2500,237.699228,8042.672102,9.764365
,0.03,15,2500,237.931482,8042.676149,9.899495
,0.03,15,2500,238.00829,8042.679317,10.034624
,0.03,15,2500,237.838725,8042.681751,10.169754
,0.03,15,2500,238.110122,8042.685027,10.304883
,0.03,15,2500,238.095537,8042.707332,10.440013
,0.03,15,2500,238.218261,8042.710942,10.575143
,0.03,15,2500,238.059478,8042.712714,10.710272
,0.03,15,2500,238.11182,8042.695107,10.845402
,0.03,15,2500,238.18545,8042.693174,10.980531
,0.03,15,2500,238.368364,8042.71568,11.115661
,0.03,15,2500,238.472337,8042.703696,11.250791
,0.03,15,2500,238.553454,8042.706,11.38592
,0.03,15,2500,238.480893,8042.708478,11.52105
,0.03,15,2500,238.64871,8042.706503,11.656179
,0.03,15,2500,238.487817,8042.71421,11.791309
,0.03,15,2500,238.572685,8042.706628,11.926439
,0.03,15,2500,238.513107,8042.694509,12.061568
,0.03,15,2500,238.767453,8042.700254,12.196698
,0.03,15,2500,238.680313,8042.713278,12.331827
,0.03,15,2500,238.76136,8042.706577,12.466957
,0.03,15,2500,238.672358,8042.709539,12.602087
,0.03,15,2500,238.835299,8042.674399,12.737216
,0.03,15,2500,238.815706,8042.678541,12.872346
,0.03,15,2500,238.76413,8042.687681,13.007475
,0.03,15,2500,238.948368,8042.702228,13.142605
,0.03,15,2500,238.299125,7872.891133,13.277735
,0.03,15,2500,237.125455,7530.759408,13.412864
,0.03,15,2500,235.745394,7188.877785,13.547994
,0.03,15,2500,234.601392,6846.884204,13.683123
,0.03,15,2500,233.071755,6504.879762,13.818253
,0.03,15,2500,231.751462,6163.241249,13.953383
,0.03,15,2500,230.31994,5821.33234,14.088512
,0.03,15,2500,228.622934,5479.653292,14.223642
,0.03,15,2500,227.39109,5137.804613,14.358771
,0.03,15,2500,225.746915,4796.144771,14.493901
,0.03,15,2500,224.32481,4454.213354,14.629031
,0.03,15,2500,222.702832,4112.634628,14.76416
,0.03,15,2500,221.134199,3771.037437,14.89929
,0.03,15,2500,219.483813,3429.533464,15.034419
,0.03,15,2500,217.91951,3088.113552,15.169549
,0.03,15,2500,216.109865,2746.681232,15.304679
,0.03,15,2500,214.37211,2405.328379,15.439808
,0.03,15,2500,212.381055,2063.998193,15.574938
,0.03,15,2500,210.473318,1722.526325,15.710067
,0.03,15,2500,208.365721,1381.336899,15.845197
,0.03,15,2500,205.920963,1040.296063,15.980327
,0.03,15,2500,203.694729,699.200543,16.115456
,0.03,15,2500,200.541459,358.25585,16.250586
,0.03,15,2500,196.282655,32.888328,16.385715
,0.03,20,2500,18.929529,267.143759,0.105101
,0.03,20,2500,39.34405,602.894294,0.24023
,0.03,20,2500,56.01579,939.539496,0.37536
,0.03,20,2500,70.172001,1277.014868,0.51049
,0.03,20,2500,83.110774,1614.935587,0.645619
,0.03,20,2500,94.928138,1953.269833,0.780749
,0.03,20,2500,105.806818,2292.274573,0.915878
,0.03,20,2500,116.192857,2631.193709,1.051008
,0.03,20,2500,125.792758,2970.468138,1.186138
,0.03,20,2500,135.208278,3309.952399,1.321267
,0.03,20,2500,143.642984,3649.682171,1.456397
,0.03,20,2500,151.664674,3989.763091,1.591526
,0.03,20,2500,159.943741,4329.838771,1.726656
,0.03,20,2500,167.672814,4670.473398,1.861786
,0.03,20,2500,174.809437,5010.999338,1.996915
,0.03,20,2500,182.118379,5351.739118,2.132045
,0.03,20,2500,189.064511,5692.520998,2.267174
,0.03,20,2500,195.641647,6033.602432,2.402304
,0.03,20,2500,202.13168,6374.952183,2.537434
,0.03,20,2500,207.830317,6716.031146,2.672563
,0.03,20,2500,212.96791,7057.688097,2.807693
,0.03,20,2500,217.122578,7399.041767,2.942822
,0.03,20,2500,221.090885,7740.801682,3.077952
,0.03,20,2500,224.561249,8038.56349,3.213082
,0.03,20,2500,225.997513,8038.636897,3.348211
,0.03,20,2500,226.61655,8038.656521,3.483341
,0.03,20,2500,227.282154,8038.677386,3.61847
,0.03,20,2500,227.541195,8038.638326,3.7536
,0.03,20,2500,227.924818,8038.660718,3.88873
,0.03,20,2500,228.2498,8038.668521,4.023859
,0.03,20,2500,228.328443,8038.680798,4.158989
,0.03,20,2500,228.606932,8038.667316,4.294118
,0.03,20,2500,228.806408,8038.66677,4.429248
,0.03,20,2500,228.948553,8038.639637,4.564378
,0.03,20,2500,229.166791,8038.650617,4.699507
,0.03,20,2500,229.217735,8038.668172,4.834637
,0.03,20,2500,229.430725,8038.672999,4.969766
,0.03,20,2500,229.404151,8038.673454,5.104896
,0.03,20,2500,229.80445,8038.666225,5.240026
,0.03,20,2500,229.668015,8038.677791,5.375155
,0.03,20,2500,229.912735,8038.685468,5.510285
,0.03,20,2500,230.004868,8038.676051,5.645414
,0.03,20,2500,230.214348,8038.715872,5.780544
,0.03,20,2500,230.319325,8038.709806,5.915674
,0.03,20,2500,230.419895,8038.687582,6.050803
,0.03,20,2500,230.462241,8038.679848,6.185933
,0.03,20,2500,230.587685,8038.729463,6.321062
,0.03,20,2500,230.532636,8038.70109,6.456192
,0.03,20,2500,230.608465,8038.684223,6.591322
,0.03,20,2500,230.651232,8038.740659,6.726451
,0.03,20,2500,231.088062,8038.734407,6.861581
,0.03,20,2500,230.957403,8038.736101,6.99671
,0.03,20,2500,230.909009,8038.718933,7.13184
,0.03,20,2500,231.141926,8038.716274,7.26697
,0.03,20,2500,231.171273,8038.720224,7.402099
,0.03,20,2500,231.08686,8038.702096,7.537229
,0.03,20,2500,231.209041,8038.771676,7.672358
,0.03,20,2500,231.438579,8038.751885,7.807488
,0.03,20,2500,231.427299,8038.809892,7.942618
,0.03,20,2500,231.470812,8038.782138,8.077747
,0.03,20,2500,231.509137,8038.836454,8.212877
,0.03,20,2500,231.451966,8038.800003,8.348006
,0.03,20,2500,231.514982,8038.785802,8.483136
,0.03,20,2500,231.641016,8038.804358,8.618266
,0.03,20,2500,231.593492,8038.793228,8.753395
,0.03,20,2500,231.784368,8038.795466,8.888525
,0.03,20,2500,231.753684,8038.772754,9.023655
,0.03,20,2500,231.9148,8038.86944,9.158784
,0.03,20,2500,231.887206,8038.830769,9.293914
,0.03,20,2500,232.046961,8038.894336,9.429043
,0.03,20,2500,232.08223,8038.876388,9.564173
,0.03,20,2500,232.049209,8038.838575,9.699303
,0.03,20,2500,232.06084,8038.841051,9.834432
,0.03,20,2500,232.124298,8038.863956,9.969562
,0.03,20,2500,232.191128,8038.841837,10.104691
,0.03,20,2500,232.203863,8038.840332,10.239821
,0.03,20,2500,232.225765,8038.851102,10.374951
,0.03,20,2500,232.376095,8038.875319,10.51008
,0.03,20,2500,232.318595,8038.85891,10.64521
,0.03,20,2500,232.549438,8038.866225,10.780339
,0.03,20,2500,232.425817,8038.828002,10.915469
,0.03,20,2500,232.599006,8038.882906,11.050599
,0.03,20,2500,232.551986,8038.874795,11.185728
,0.03,20,2500,232.524605,8038.853173,11.320858
,0.03,20,2500,232.661714,8038.885059,11.455987
,0.03,20,2500,232.678217,8038.866612,11.591117
,0.03,20,2500,232.736602,8038.860308,11.726247
,0.03,20,2500,232.656857,8038.856338,11.861376
,0.03,20,2500,232.692601,8038.890536,11.996506
,0.03,20,2500,232.699815,8038.880864,12.131635
,0.03,20,2500,232.542459,8038.859788,12.266765
,0.03,20,2500,232.673844,8038.861445,12.401895
,0.03,20,2500,232.792482,8038.839704,12.537024
,0.03,20,2500,232.793013,8038.876973,12.672154
,0.03,20,2500,232.802341,8038.878386,12.807283
,0.03,20,2500,232.955338,8038.906686,12.942413
,0.03,20,2500,232.997194,8038.889916,13.077543
,0.03,20,2500,233.010905,8034.101871,13.212672
,0.03,20,2500,231.822587,7692.099635,13.347802
,0.03,20,2500,230.362685,7350.578026,13.482931
,0.03,20,2500,229.077645,7008.76084,13.618061
,0.03,20,2500,228.048699,6667.284619,13.753191
,0.03,20,2500,226.371753,6325.654316,13.88832
,0.03,20,2500,225.048868,5984.27806,14.02345
,0.03,20,2500,223.493783,5642.614986,14.158579
,0.03,20,2500,222.007216,5301.160611,14.293709
,0.03,20,2500,220.516463,4959.657174,14.428839
,0.03,20,2500,218.937136,4618.023306,14.563968
,0.03,20,2500,217.157199,4276.711233,14.699098
,0.03,20,2500,215.421636,3935.429811,14.834227
,0.03,20,2500,213.757662,3594.171493,14.969357
,0.03,20,2500,212.292656,3252.968416,15.104487
,0.03,20,2500,210.30506,2911.826782,15.239616
,0.03,20,2500,208.441454,2570.675975,15.374746
,0.03,20,2500,206.575596,2229.671483,15.509875
,0.03,20,2500,204.437492,1888.462979,15.645005
,0.03,20,2500,202.348592,1547.560443,15.780135
,0.03,20,2500,199.900032,1206.613635,15.915264
,0.03,20,2500,197.219676,865.898748,16.050394
,0.03,20,2500,194.324917,525.248328,16.185523
,0.03,20,2500,190.636332,184.702806,16.320653
,0.03,25,2500,9.074514,104.384292,0.040038
,0.03,25,2500,34.506052,438.99494,0.175168
,0.03,25,2500,53.438402,775.368047,0.310298
,0.03,25,2500,67.867828,1112.78431,0.445427
,0.03,25,2500,80.427499,1450.784977,0.580557
,0.03,25,2500,91.724018,1789.258923,0.715686
,0.03,25,2500,102.10642,2128.337031,0.850816
,0.03,25,2500,112.150679,2467.426072,0.985946
,0.03,25,2500,121.127952,2806.83772,1.121075
,0.03,25,2500,129.896185,3146.389864,1.256205
,0.03,25,2500,138.217671,3486.252507,1.391334
,0.03,25,2500,146.305329,3826.354484,1.526464
,0.03,25,2500,154.51137,4166.59891,1.661594
,0.03,25,2500,162.078684,4506.943662,1.796723
,0.03,25,2500,169.448,4847.874174,1.931853
,0.03,25,2500,176.449962,5188.666852,2.066982
,0.03,25,2500,183.202531,5529.632838,2.202112
,0.03,25,2500,189.59001,5870.714384,2.337242
,0.03,25,2500,196.044001,6212.043291,2.472371
,0.03,25,2500,202.078517,6553.214798,2.607501
,0.03,25,2500,208.044843,6894.931564,2.74263
,0.03,25,2500,213.79504,7236.37864,2.87776
,0.03,25,2500,219.012436,7578.292602,3.01289
,0.03,25,2500,224.496682,7920.063027,3.148019
,0.03,25,2500,228.009473,8042.107435,3.283149
,0.03,25,2500,229.189864,8042.113385,3.418278
,0.03,25,2500,229.805774,8042.106939,3.553408
,0.03,25,2500,230.464333,8042.140855,3.688538
,0.03,25,2500,230.81388,8042.184842,3.823667
,0.03,25,2500,231.152685,8042.2225,3.958797
,0.03,25,2500,231.371886,8042.228593,4.093926
,0.03,25,2500,231.736383,8042.26299,4.229056
,0.03,25,2500,231.958507,8042.273182,4.364186
,0.03,25,2500,232.038089,8042.21603,4.499315
,0.03,25,2500,232.216595,8042.228965,4.634445
,0.03,25,2500,232.444734,8042.199209,4.769574
,0.03,25,2500,232.437154,8042.256881,4.904704
,0.03,25,2500,232.623999,8042.259026,5.039834
,0.03,25,2500,232.784733,8042.255395,5.174963
,0.03,25,2500,232.84883,8042.207823,5.310093
,0.03,25,2500,233.030199,8042.239902,5.445222
,0.03,25,2500,233.123664,8042.236319,5.580352
,0.03,25,2500,233.423543,8042.215677,5.715482
,0.03,25,2500,233.367515,8042.195702,5.850611
,0.03,25,2500,233.416609,8042.234964,5.985741
,0.03,25,2500,233.412417,8042.213489,6.12087
,0.03,25,2500,233.687366,8042.227231,6.256
,0.03,25,2500,233.731169,8042.23123,6.39113
,0.03,25,2500,233.902857,8042.261024,6.526259
,0.03,25,2500,233.913857,8042.234976,6.661389
,0.03,25,2500,233.934802,8042.273419,6.796518
,0.03,25,2500,234.072664,8042.225989,6.931648
,0.03,25,2500,234.120568,8042.266221,7.066778
,0.03,25,2500,234.15157,8042.221697,7.201907
,0.03,25,2500,234.170576,8042.244033,7.337037
,0.03,25,2500,234.268598,8042.233562,7.472166
,0.03,25,2500,234.323203,8042.247908,7.607296
,0.03,25,2500,234.208389,8042.262333,7.742426
,0.03,25,2500,234.395742,8042.238414,7.877555
,0.03,25,2500,234.485219,8042.246755,8.012685
,0.03,25,2500,234.439543,8042.240121,8.147814
,0.03,25,2500,234.600674,8042.254563,8.282944
,0.03,25,2500,234.636864,8042.258341,8.418074
,0.03,25,2500,234.743865,8042.233084,8.553203
,0.03,25,2500,234.735548,8042.259641,8.688333
,0.03,25,2500,234.756541,8042.259967,8.823463
,0.03,25,2500,234.802784,8042.266044,8.958592
,0.03,25,2500,234.866696,8042.236522,9.093722
,0.03,25,2500,234.91258,8042.246602,9.228851
,0.03,25,2500,234.89283,8042.263798,9.363981
,0.03,25,2500,235.084894,8042.246037,9.499111
,0.03,25,2500,235.140299,8042.266427,9.63424
,0.03,25,2500,235.037886,8042.275193,9.76937
,0.03,25,2500,234.969969,8042.260889,9.904499
,0.03,25,2500,235.036797,8042.275592,10.039629
,0.03,25,2500,235.095072,8042.284028,10.174759
,0.03,25,2500,235.240836,8042.279965,10.309888
,0.03,25,2500,235.208444,8042.277732,10.445018
,0.03,25,2500,235.197174,8042.293168,10.580147
,0.03,25,2500,235.219431,8042.272464,10.715277
,0.03,25,2500,235.285074,8042.28613,10.850407
,0.03,25,2500,235.378525,8042.297598,10.985536
,0.03,25,2500,235.230463,8042.282963,11.120666
,0.03,25,2500,235.462062,8042.303474,11.255795
,0.03,25,2500,235.236953,8042.306657,11.390925
,0.03,25,2500,235.459127,8042.27874,11.526055
,0.03,25,2500,235.369028,8042.288868,11.661184
,0.03,25,2500,235.53778,8042.319587,11.796314
,0.03,25,2500,235.406504,8042.296412,11.931443
,0.03,25,2500,235.554226,8042.328524,12.066573
,0.03,25,2500,235.477959,8042.319994,12.201703
,0.03,25,2500,235.584496,8042.312783,12.336832
,0.03,25,2500,235.676628,8042.339261,12.471962
,0.03,25,2500,235.687619,8042.345315,12.607091
,0.03,25,2500,235.719051,8042.323875,12.742221
,0.03,25,2500,235.749874,8042.369634,12.877351
,0.03,25,2500,235.745631,8042.359192,13.01248
,0.03,25,2500,235.831197,8042.385479,13.14761
,0.03,25,2500,234.928022,7859.369492,13.282739
,0.03,25,2500,233.565584,7517.224827,13.417869
,0.03,25,2500,232.181802,7175.459249,13.552999
,0.03,25,2500,230.867106,6833.516234,13.688128
,0.03,25,2500,229.480593,6491.650333,13.823258
,0.03,25,2500,227.893843,6149.966948,13.958387
,0.03,25,2500,226.429239,5808.043025,14.093517
,0.03,25,2500,224.798036,5466.527965,14.228647
,0.03,25,2500,223.472507,5124.773405,14.363776
,0.03,25,2500,221.96591,4783.152255,14.498906
,0.03,25,2500,220.178685,4441.307986,14.634035
,0.03,25,2500,218.806601,4099.752713,14.769165
,0.03,25,2500,216.760613,3758.309398,14.904295
,0.03,25,2500,215.212794,3416.952053,15.039424
,0.03,25,2500,213.384544,3075.54455,15.174554
,0.03,25,2500,211.466297,2734.193415,15.309683
,0.03,25,2500,209.72647,2392.893309,15.444813
,0.03,25,2500,207.725403,2051.708902,15.579943
,0.03,25,2500,205.584112,1710.36745,15.715072
,0.03,25,2500,203.233401,1369.313815,15.850202
,0.03,25,2500,200.757844,1028.342032,15.985331
,0.03,25,2500,197.864287,687.479277,16.120461
,0.03,25,2500,194.39494,346.685255,16.255591
,0.03,25,2500,188.773695,17.809385,16.39072
,7,30,2500,22.225814,276.0165,0.110106
,7,30,2500,43.089363,609.916188,0.245235
,7,30,2500,59.867329,944.798246,0.380365
,7,30,2500,73.596401,1280.438574,0.515494
,7,30,2500,86.108311,1616.573892,0.650624
,7,30,2500,97.514495,1953.169261,0.785754
,7,30,2500,107.971859,2290.218455,0.920883
,7,30,2500,118.023116,2627.372257,1.056013
,7,30,2500,127.646599,2964.863418,1.191142
,7,30,2500,137.087874,3302.489983,1.326272
,7,30,2500,145.902459,3640.405063,1.461402
,7,30,2500,154.221724,3978.62805,1.596531
,7,30,2500,162.363152,4316.931727,1.731661
,7,30,2500,170.283686,4655.736327,1.86679
,7,30,2500,178.226947,4994.478834,2.00192
,7,30,2500,185.587093,5333.334526,2.13705
,7,30,2500,192.798037,5672.439682,2.272179
,7,30,2500,200.076611,6011.806195,2.407309
,7,30,2500,206.88604,6351.047109,2.542438
,7,30,2500,213.570758,6690.581781,2.677568
,7,30,2500,220.267639,7030.407638,2.812698
,7,30,2500,226.875844,7370.179951,2.947827
,7,30,2500,233.246444,7710.307835,3.082957
,7,30,2500,239.04884,7994.813666,3.218086
,7,30,2500,241.315097,7994.932166,3.353216
,7,30,2500,242.629469,7995.016064,3.488346
,7,30,2500,243.319538,7995.050742,3.623475
,7,30,2500,243.812391,7995.055075,3.758605
,7,30,2500,244.488446,7995.107818,3.893734
,7,30,2500,244.726894,7995.091834,4.028864
,7,30,2500,245.006709,7995.137055,4.163994
,7,30,2500,245.348042,7995.096508,4.299123
,7,30,2500,245.543215,7995.066572,4.434253
,7,30,2500,245.728573,7995.060818,4.569382
,7,30,2500,246.000764,7995.148085,4.704512
,7,30,2500,245.969739,7995.141619,4.839642
,7,30,2500,246.284062,7995.110603,4.974771
,7,30,2500,246.23009,7995.13754,5.109901
,7,30,2500,246.556733,7995.143625,5.24503
,7,30,2500,246.73742,7995.162304,5.38016
,7,30,2500,246.883174,7995.098388,5.51529
,7,30,2500,246.987109,7995.147841,5.650419
,7,30,2500,247.054193,7995.108685,5.785549
,7,30,2500,247.163781,7995.160388,5.920678
,7,30,2500,247.098575,7995.163101,6.055808
,7,30,2500,247.355839,7995.155931,6.190938
,7,30,2500,247.3849,7995.135632,6.326067
,7,30,2500,247.576418,7995.171611,6.461197
,7,30,2500,247.573194,7995.194124,6.596326
,7,30,2500,247.736901,7995.148841,6.731456
,7,30,2500,247.674212,7995.179298,6.866586
,7,30,2500,247.753603,7995.134825,7.001715
,7,30,2500,247.887232,7995.163042,7.136845
,7,30,2500,248.003065,7995.155863,7.271974
,7,30,2500,248.27629,7995.191893,7.407104
,7,30,2500,248.215683,7995.16129,7.542234
,7,30,2500,248.15045,7995.127502,7.677363
,7,30,2500,248.246023,7995.178521,7.812493
,7,30,2500,248.24847,7995.205257,7.947622
,7,30,2500,248.216452,7995.138567,8.082752
,7,30,2500,248.183545,7995.168506,8.217882
,7,30,2500,248.540002,7995.179998,8.353011
,7,30,2500,248.70199,7995.189873,8.488141
,7,30,2500,248.589105,7995.170525,8.623271
,7,30,2500,248.599613,7995.167074,8.7584
,7,30,2500,248.545094,7995.160445,8.89353
,7,30,2500,248.711479,7995.181386,9.028659
,7,30,2500,248.805713,7995.132706,9.163789
,7,30,2500,248.624268,7995.174126,9.298919
,7,30,2500,248.863316,7995.19862,9.434048
,7,30,2500,248.898677,7995.115495,9.569178
,7,30,2500,249.003259,7995.176819,9.704307
,7,30,2500,249.054103,7995.141801,9.839437
,7,30,2500,249.09173,7995.113042,9.974567
,7,30,2500,248.948871,7995.153389,10.109696
,7,30,2500,249.280751,7995.09364,10.244826
,7,30,2500,249.118173,7995.180373,10.379955
,7,30,2500,249.232385,7995.121819,10.515085
,7,30,2500,249.371175,7995.163114,10.650215
,7,30,2500,249.269567,7995.121628,10.785344
,7,30,2500,249.153696,7995.142579,10.920474
,7,30,2500,249.437141,7995.121893,11.055603
,7,30,2500,249.542701,7995.154658,11.190733
,7,30,2500,249.550983,7995.157017,11.325863
,7,30,2500,249.306691,7995.123353,11.460992
,7,30,2500,249.180278,7995.141816,11.596122
,7,30,2500,249.543576,7995.117142,11.731251
,7,30,2500,249.47315,7995.131437,11.866381
,7,30,2500,249.79955,7995.170067,12.001511
,7,30,2500,249.699308,7995.160215,12.13664
,7,30,2500,249.576788,7995.129544,12.27177
,7,30,2500,249.528743,7995.160717,12.406899
,7,30,2500,249.621739,7995.151435,12.542029
,7,30,2500,249.803746,7995.201747,12.677159
,7,30,2500,249.756833,7995.151099,12.812288
,7,30,2500,249.972341,7995.165564,12.947418
,7,30,2500,249.893049,7995.177452,13.082547
,7,30,2500,249.884156,7977.451142,13.217677
,7,30,2500,248.530593,7637.26823,13.352807
,7,30,2500,247.270285,7297.351602,13.487936
,7,30,2500,245.939413,6957.220794,13.623066
,7,30,2500,244.489923,6617.264056,13.758195
,7,30,2500,243.41826,6277.521385,13.893325
,7,30,2500,242.050725,5937.652516,14.028455
,7,30,2500,240.702391,5597.882686,14.163584
,7,30,2500,239.120937,5258.062834,14.298714
,7,30,2500,237.723936,4918.369495,14.433843
,7,30,2500,236.375249,4578.695922,14.568973
,7,30,2500,234.693081,4238.784589,14.704103
,7,30,2500,233.224519,3899.246271,14.839232
,7,30,2500,231.662511,3559.662629,14.974362
,7,30,2500,230.095461,3220.18892,15.109491
,7,30,2500,228.334127,2880.789821,15.244621
,7,30,2500,226.538415,2541.413692,15.379751
,7,30,2500,224.788785,2201.960933,15.51488
,7,30,2500,222.713687,1862.534703,15.65001
,7,30,2500,220.710927,1523.282604,15.785139
,7,30,2500,218.448424,1184.107652,15.920269
,7,30,2500,215.95319,844.999668,16.055399
,7,30,2500,213.109796,505.971303,16.190528
,7,30,2500,209.460019,166.919647,16.325658
,7,60,2500,9.278693,115.98333,0.045043
,7,60,2500,33.752872,449.082358,0.180173
,7,60,2500,52.727625,783.602626,0.315302
,7,60,2500,68.01553,1118.956467,0.450432
,7,60,2500,81.330917,1454.888034,0.585562
,7,60,2500,93.102906,1791.365895,0.720691
,7,60,2500,104.162879,2128.328833,0.855821
,7,60,2500,114.830254,2465.361687,0.99095
,7,60,2500,125.144313,2802.713175,1.12608
,7,60,2500,134.366817,3140.385401,1.26121
,7,60,2500,143.781499,3478.153699,1.396339
,7,60,2500,152.110916,3816.355725,1.531469
,7,60,2500,160.582025,4154.551267,1.666598
,7,60,2500,168.868526,4493.072645,1.801728
,7,60,2500,176.706779,4832.043763,1.936858
,7,60,2500,184.207542,5170.868747,2.071987
,7,60,2500,192.054784,5509.839102,2.207117
,7,60,2500,199.365373,5849.133077,2.342246
,7,60,2500,206.321204,6188.434043,2.477376
,7,60,2500,213.281375,6528.073414,2.612506
,7,60,2500,220.198012,6867.604773,2.747635
,7,60,2500,226.955387,7207.409692,2.882765
,7,60,2500,233.017078,7547.417855,3.017894
,7,60,2500,239.199398,7887.743196,3.153024
,7,60,2500,242.7952,7996.007857,3.288154
,7,60,2500,244.196314,7996.040026,3.423283
,7,60,2500,244.793653,7996.020279,3.558413
,7,60,2500,245.248102,7996.035272,3.693542
,7,60,2500,245.651763,7996.080872,3.828672
,7,60,2500,245.955131,7996.090635,3.963802
,7,60,2500,246.317582,7996.105806,4.098931
,7,60,2500,246.502721,7996.082956,4.234061
,7,60,2500,246.795255,7996.057595,4.36919
,7,60,2500,246.99095,7996.145165,4.50432
,7,60,2500,247.001739,7996.120084,4.63945
,7,60,2500,247.292172,7996.106528,4.774579
,7,60,2500,247.297392,7996.130761,4.909709
,7,60,2500,247.531971,7996.104995,5.044838
,7,60,2500,247.808021,7996.164172,5.179968
,7,60,2500,247.727304,7996.157118,5.315098
,7,60,2500,247.928799,7996.158724,5.450227
,7,60,2500,248.056332,7996.116655,5.585357
,7,60,2500,248.216903,7996.171074,5.720486
,7,60,2500,248.248077,7996.179532,5.855616
,7,60,2500,248.291645,7996.156792,5.990746
,7,60,2500,248.52439,7996.147797,6.125875
,7,60,2500,248.46594,7996.18526,6.261005
,7,60,2500,248.645189,7996.180995,6.396134
,7,60,2500,248.549143,7996.148536,6.531264
,7,60,2500,248.724938,7996.204575,6.666394
,7,60,2500,248.803084,7996.191188,6.801523
,7,60,2500,248.797608,7996.237771,6.936653
,7,60,2500,248.920164,7996.164779,7.071782
,7,60,2500,248.907527,7996.207104,7.206912
,7,60,2500,249.021255,7996.154557,7.342042
,7,60,2500,249.10015,7996.215519,7.477171
,7,60,2500,249.067351,7996.180712,7.612301
,7,60,2500,249.034929,7996.191503,7.74743
,7,60,2500,249.2497,7996.16294,7.88256
,7,60,2500,249.114911,7996.205183,8.01769
,7,60,2500,249.29155,7996.182975,8.152819
,7,60,2500,249.29876,7996.183509,8.287949
,7,60,2500,249.347251,7996.194663,8.423078
,7,60,2500,249.332298,7996.184374,8.558208
,7,60,2500,249.45935,7996.15814,8.693338
,7,60,2500,249.637364,7996.163735,8.828467
,7,60,2500,249.622192,7996.195055,8.963597
,7,60,2500,249.752736,7996.216529,9.098727
,7,60,2500,249.678582,7996.191908,9.233856
,7,60,2500,249.750122,7996.185185,9.368986
,7,60,2500,249.771799,7996.239825,9.504115
,7,60,2500,249.770753,7996.1984,9.639245
,7,60,2500,249.889865,7996.181748,9.774375
,7,60,2500,249.828099,7996.20421,9.909504
,7,60,2500,249.872465,7996.207267,10.044634
,7,60,2500,249.924263,7996.218558,10.179763
,7,60,2500,249.95715,7996.183486,10.314893
,7,60,2500,250.068448,7996.220022,10.450023
,7,60,2500,249.906297,7996.244291,10.585152
,7,60,2500,250.195969,7996.246563,10.720282
,7,60,2500,250.030926,7996.187475,10.855411
,7,60,2500,250.140594,7996.195206,10.990541
,7,60,2500,250.171602,7996.243295,11.125671
,7,60,2500,250.249332,7996.218991,11.2608
,7,60,2500,250.107609,7996.183655,11.39593
,7,60,2500,250.233996,7996.257478,11.531059
,7,60,2500,250.302861,7996.211998,11.666189
,7,60,2500,250.269619,7996.224737,11.801319
,7,60,2500,250.322779,7996.249957,11.936448
,7,60,2500,250.358841,7996.183307,12.071578
,7,60,2500,250.338697,7996.248114,12.206707
,7,60,2500,250.476556,7996.182688,12.341837
,7,60,2500,250.531531,7996.217893,12.476967
,7,60,2500,250.488634,7996.170777,12.612096
,7,60,2500,250.614614,7996.220801,12.747226
,7,60,2500,250.509553,7996.237514,12.882355
,7,60,2500,250.586876,7996.208239,13.017485
,7,60,2500,250.684552,7996.216467,13.152615
,7,60,2500,249.8742,7801.715994,13.287744
,7,60,2500,248.69132,7461.794521,13.422874
,7,60,2500,247.412488,7121.643762,13.558003
,7,60,2500,246.03053,6781.767931,13.693133
,7,60,2500,244.735812,6441.742877,13.828263
,7,60,2500,243.301409,6101.984196,13.963392
,7,60,2500,242.05702,5762.078338,14.098522
,7,60,2500,240.627843,5422.191743,14.233651
,7,60,2500,239.214319,5082.445741,14.368781
,7,60,2500,237.953681,4742.728544,14.503911
,7,60,2500,236.3561,4402.722494,14.63904
,7,60,2500,234.788273,4062.965163,14.77417
,7,60,2500,233.185465,3723.410217,14.909299
,7,60,2500,231.785052,3383.786956,15.044429
,7,60,2500,230.113758,3044.234617,15.179559
,7,60,2500,228.259049,2704.711549,15.314688
,7,60,2500,226.575334,2365.249023,15.449818
,7,60,2500,224.752609,2025.872459,15.584947
,7,60,2500,222.756117,1686.359901,15.720077
,7,60,2500,220.677868,1347.039697,15.855207
,7,60,2500,218.34983,1007.791739,15.990336
,7,60,2500,215.848536,668.598973,16.125466
,7,60,2500,212.679704,329.421576,16.260595
,7,60,2500,207.695446,15.519829,16.395725
,7,90,2500,24.926903,288.062536,0.11511
,7,90,2500,46.615434,621.93489,0.25024
,7,90,2500,65.562078,956.521407,0.38537
,7,90,2500,81.035075,1291.990007,0.520499
,7,90,2500,95.436331,1627.953937,0.655629
,7,90,2500,108.613822,1964.38595,0.790758
,7,90,2500,122.69174,2301.172866,0.925888
,7,90,2500,135.008919,2638.226195,1.061018
,7,90,2500,146.866989,2975.634214,1.196147
,7,90,2500,156.371667,3313.451749,1.331277
,7,90,2500,166.197757,3651.491641,1.466406
,7,90,2500,175.653299,3989.700973,1.601536
,7,90,2500,184.839723,4328.231157,1.736666
,7,90,2500,193.763756,4667.245074,1.871795
,7,90,2500,203.046166,5006.090958,2.006925
,7,90,2500,211.117972,5345.179498,2.142054
,7,90,2500,218.707004,5684.482959,2.277184
,7,90,2500,225.827193,6024.065229,2.412314
,7,90,2500,233.354019,6363.554307,2.547443
,7,90,2500,240.89554,6703.280106,2.682573
,7,90,2500,247.478805,7043.339013,2.817702
,7,90,2500,254.848485,7383.388342,2.952832
,7,90,2500,261.662545,7723.799584,3.087962
,7,90,2500,267.919094,7995.842556,3.223091
,7,90,2500,270.209314,7995.902876,3.358221
,7,90,2500,271.221239,7995.969678,3.49335
,7,90,2500,271.873902,7996.018599,3.62848
,7,90,2500,272.359564,7996.021912,3.76361
,7,90,2500,272.823874,7996.063019,3.898739
,7,90,2500,273.156464,7996.027252,4.033869
,7,90,2500,273.543701,7996.040367,4.168998
,7,90,2500,273.700278,7996.092499,4.304128
,7,90,2500,274.05865,7996.092517,4.439258
,7,90,2500,274.196692,7996.11611,4.574387
,7,90,2500,274.3168,7996.113172,4.709517
,7,90,2500,274.552145,7996.110063,4.844646
,7,90,2500,274.676816,7996.107315,4.979776
,7,90,2500,274.822345,7996.135188,5.114906
,7,90,2500,274.870381,7996.125289,5.250035
,7,90,2500,275.110743,7996.146193,5.385165
,7,90,2500,275.154193,7996.10734,5.520294
,7,90,2500,275.424897,7996.165212,5.655424
,7,90,2500,275.492174,7996.142227,5.790554
,7,90,2500,275.732755,7996.159175,5.925683
,7,90,2500,275.642981,7996.125695,6.060813
,7,90,2500,275.765112,7996.123834,6.195942
,7,90,2500,276.036354,7996.180739,6.331072
,7,90,2500,275.946222,7996.178982,6.466202
,7,90,2500,276.010026,7996.129073,6.601331
,7,90,2500,276.270012,7996.132943,6.736461
,7,90,2500,276.290749,7996.174477,6.87159
,7,90,2500,276.327034,7996.189877,7.00672
,7,90,2500,276.397626,7996.154135,7.14185
,7,90,2500,276.544907,7996.198946,7.276979
,7,90,2500,276.556015,7996.188504,7.412109
,7,90,2500,276.583048,7996.197568,7.547238
,7,90,2500,276.696888,7996.22512,7.682368
,7,90,2500,276.705521,7996.188786,7.817498
,7,90,2500,276.923465,7996.179008,7.952627
,7,90,2500,276.944341,7996.220548,8.087757
,7,90,2500,276.792753,7996.203341,8.222886
,7,90,2500,277.00317,7996.233917,8.358016
,7,90,2500,277.104711,7996.22525,8.493146
,7,90,2500,277.234252,7996.230643,8.628275
,7,90,2500,277.316173,7996.24695,8.763405
,7,90,2500,277.249369,7996.227316,8.898535
,7,90,2500,277.263587,7996.22097,9.033664
,7,90,2500,277.539296,7996.241368,9.168794
,7,90,2500,277.544981,7996.192015,9.303923
,7,90,2500,277.465829,7996.213527,9.439053
,7,90,2500,277.644255,7996.233847,9.574183
,7,90,2500,277.583207,7996.212469,9.709312
,7,90,2500,277.489714,7996.233384,9.844442
,7,90,2500,277.65121,7996.235146,9.979571
,7,90,2500,277.774208,7996.23134,10.114701
,7,90,2500,277.756611,7996.237557,10.249831
,7,90,2500,277.865576,7996.258957,10.38496
,7,90,2500,277.801509,7996.234477,10.52009
,7,90,2500,277.810798,7996.234869,10.655219
,7,90,2500,277.988454,7996.246231,10.790349
,7,90,2500,278.103588,7996.277807,10.925479
,7,90,2500,277.985946,7996.25209,11.060608
,7,90,2500,278.047003,7996.249676,11.195738
,7,90,2500,278.224034,7996.221336,11.330867
,7,90,2500,278.073638,7996.202192,11.465997
,7,90,2500,278.242321,7996.254842,11.601127
,7,90,2500,278.182396,7996.212679,11.736256
,7,90,2500,278.259877,7996.244672,11.871386
,7,90,2500,278.402193,7996.234727,12.006515
,7,90,2500,278.412147,7996.257961,12.141645
,7,90,2500,278.45457,7996.267667,12.276775
,7,90,2500,278.342943,7996.276916,12.411904
,7,90,2500,278.526376,7996.277609,12.547034
,7,90,2500,278.40355,7996.2487,12.682163
,7,90,2500,278.69709,7996.251989,12.817293
,7,90,2500,278.480332,7996.233059,12.952423
,7,90,2500,278.694457,7996.270737,13.087552
,7,90,2500,278.561296,7965.88449,13.222682
,7,90,2500,277.302349,7625.431874,13.357811
,7,90,2500,276.133577,7285.200086,13.492941
,7,90,2500,274.854167,6944.821482,13.628071
,7,90,2500,273.643177,6604.771803,13.7632
,7,90,2500,272.260249,6264.543129,13.89833
,7,90,2500,270.893503,5924.286394,14.033459
,7,90,2500,269.614975,5584.222798,14.168589
,7,90,2500,268.084659,5244.106628,14.303719
,7,90,2500,266.724199,4904.163877,14.438848
,7,90,2500,265.263635,4564.212917,14.573978
,7,90,2500,263.851985,4223.894201,14.709107
,7,90,2500,262.382319,3883.989691,14.844237
,7,90,2500,260.860922,3544.063154,14.979367
,7,90,2500,259.229743,3204.258417,15.114496
,7,90,2500,257.646067,2864.452436,15.249626
,7,90,2500,256.072104,2524.673796,15.384755
,7,90,2500,254.279757,2184.941418,15.519885
,7,90,2500,252.387614,1845.11321,15.655015
,7,90,2500,250.420609,1505.447806,15.790144
,7,90,2500,248.351213,1165.842479,15.925274
,7,90,2500,246.067827,826.334165,16.060403
,7,90,2500,243.492493,486.837139,16.195533
,7,90,2500,240.255098,147.296934,16.330663
,7,90,2500,17.52637,3.532347,16.410739